Workbook
Name HMax: Settings!$C$10
Name HMin: Settings!$C$9
Name OverdueDays: Settings!$C$11
Name ReportDate: Settings!$C$4
Name Target: Settings!$C$8
Name Trigger: Settings!$C$5
Name TriggerMonth: Settings!$C$6
Name WatchBand: Settings!$C$7

Sheet Read_Me
A1: Planting and Monitoring Data Kit (illustrative data)
A2: Built by Les' Aullian Achmad Argito for the CarbonEthics Operations & Science Intern application, October 2026.
A4: Read this first | B4: Every site, plot, count and date in this file is invented to show how the sheets work. Nothing here describes a real CarbonEthics site, partner or client.
A5: What it is for | B5: Keeping planting and survival data clean enough to report: one row per plot planted, one row per plot visit, automatic checks, and a status line per plot that tells the team what to do next.
A6: How to use it | B6: 1) Set the report date and thresholds in Settings. 2) Add plots to Planting_Log. 3) Add one Monitoring row per plot visit (yellow cells only; grey cells are formulas). 4) Read the QA_Flags column and correct flagged rows at the source. 5) Read Plot_Status and Dashboard for actions. 6) Copy grey formula rows down when you add rows.
A7: Data rule 1 | B7: Counts are cumulative since planting: Alive + Dead + Missing must equal seedlings planted plus seedlings replanted on earlier visits.
A8: Data rule 2 | B8: Replanting is recorded on the visit where it happens, after that visit's count; it enters the expected total from the next visit.
A9: Data rule 3 | B9: Plot_Status uses only rows that pass every check. A flagged row is corrected, never deleted, and the plot shows its last clean census until then.
A10: Data rule 4 | B10: Stocking = living trees / seedlings in the original design (drives the replanting trigger). Survival = living trees / all seedlings ever planted on the plot (shows what replanting cost).
A11: QA check 1: Unknown plot | B11: Plot ID not found in Planting_Log (typos such as B3 for B03).
A12: QA check 2: Visit before planting | B12: Visit date earlier than the planting date (often a mistyped year).
A13: QA check 3: Count mismatch | B13: Alive + Dead + Missing does not equal the expected total.
A14: QA check 4: Alive rose without replanting | B14: More living trees than at the previous visit plus anything replanted since.
A15: QA check 5: Duplicate visit | B15: Same plot and date entered twice.
... A20: Google Sheets | B20: Uses COUNTIFS, SUMIFS, AVERAGEIFS, SUMPRODUCT and INDEX/MATCH only, which work in Google Sheets and Excel.

Sheet Dashboard
A1: Dashboard
A2: Illustrative data. Figures update from Planting_Log and Monitoring; status uses clean rows only.
A3: Report date | B3: =ReportDate -> 46295
A5: Seedlings planted (design) | C5: Replanted to date | E5: Alive at last clean visit | G5: Stocking vs design
A6: =Site_Summary!C8 -> 5900 | C6: =Site_Summary!D8 -> 272 | E6: =Site_Summary!E8 -> 4638 | G6: =Site_Summary!F8 -> 0.78610169
A8: Plots to replant | C8: Seedlings to order | E8: Plots with census overdue | G8: Flagged rows to correct
A9: =Site_Summary!G8 -> 2 | C9: =Site_Summary!H8 -> 135 | E9: =Site_Summary!I8 -> 5 | G9: =COUNTIF(Monitoring!$Z$5:$Z$200,">0") -> 9

Sheet Settings
A1: Settings
A2: Change these values; every formula reads them by name.
A3: Name | B3: Setting | C3: Value | E3: Sites | F3: Species | G3: Causes | H3: Observers | I3: Visit types
A4: ReportDate | B4: Report date | C4: 46295 | E4: Site A - seaward fringe | F4: Rhizophora mucronata | G4: Wave/scour | H4: FS-1 (field staff) | I4: Census
A5: Trigger | B5: Replant when stocking is below | C5: 0.7 | E5: Site B - pond dyke | F5: Rhizophora apiculata | G5: Barnacles | H5: FS-2 (field staff) | I5: Replanting
A6: TriggerMonth | B6: Apply the trigger from census month | C6: 6 | E6: Site C - sheltered lagoon | F6: Avicennia marina | G6: Sediment burial | H6: PL-1 (partner lead) | I6: Follow-up
A7: WatchBand | B7: Watch band above the trigger | C7: 0.1 | F7: Sonneratia alba | G7: Crab damage | H7: PL-2 (partner lead)
A8: Target | B8: Replant up to this stocking | C8: 0.8 | G8: Grazing | H8: PL-3 (partner lead)
A9: HMin | B9: Plausible mean height, minimum (cm) | C9: 10 | G9: Debris/plastic
A10: HMax | B10: Plausible mean height, maximum (cm) | C10: 250 | G10: Human disturbance
A11: OverdueDays | B11: Census overdue after (days) | C11: 100 | G11: Unknown

Sheet Planting_Log
A1: Planting log
A2: One row per plot planted. Yellow = input. Illustrative data.
A4: Plot ID | B4: Site | C4: Zone | D4: Planted on | E4: Species | F4: Seedling source | G4: Seedlings planted | H4: Spacing (m) | I4: Partner group | J4: GPS waypoint ID | K4: Photo point ID | L4: Notes
A5: A01 | B5: Site A - seaward fringe | C5: Open fringe | D5: 45948 | E5: Rhizophora mucronata | F5: Partner nursery | G5: 500 | H5: 1 | I5: Partner group 1 | J5: WP-A01 | K5: PP-A01
A6: A02 | B6: Site A - seaward fringe | C6: Open fringe | D6: 45948 | E6: Rhizophora mucronata | F6: Partner nursery | G6: 500 | H6: 1 | I6: Partner group 1 | J6: WP-A02 | K6: PP-A02
A7: A03 | B7: Site A - seaward fringe | C7: Behind wave breaker | D7: 45948 | E7: Rhizophora mucronata | F7: Partner nursery | G7: 500 | H7: 1 | I7: Partner group 1 | J7: WP-A03 | K7: PP-A03
A8: A04 | B8: Site A - seaward fringe | C8: Behind wave breaker | D8: 45949 | E8: Rhizophora mucronata | F8: Partner nursery | G8: 450 | H8: 1 | I8: Partner group 1 | J8: WP-A04 | K8: PP-A04
A9: B01 | B9: Site B - pond dyke | C9: Dyke crest | D9: 46046 | E9: Rhizophora mucronata | F9: Partner nursery | G9: 600 | H9: 1 | I9: Partner group 2 | J9: WP-B01 | K9: PP-B01
A10: B02 | B10: Site B - pond dyke | C10: Dyke crest | D10: 46046 | E10: Rhizophora mucronata | F10: Partner nursery | G10: 600 | H10: 1 | I10: Partner group 2 | J10: WP-B02 | K10: PP-B02
A11: B03 | B11: Site B - pond dyke | C11: Pond floor | D11: 46046 | E11: Rhizophora mucronata | F11: Partner nursery | G11: 550 | H11: 1 | I11: Partner group 2 | J11: WP-B03 | K11: PP-B03
A12: B04 | B12: Site B - pond dyke | C12: Pond floor | D12: 46046 | E12: Rhizophora mucronata | F12: Partner nursery | G12: 600 | H12: 1 | I12: Partner group 2 | J12: WP-B04 | K12: PP-B04
A13: C01 | B13: Site C - sheltered lagoon | C13: Lagoon edge | D13: 46095 | E13: Avicennia marina | F13: Wild propagules, partner nursery | G13: 400 | H13: 1.5 | I13: Partner group 3 | J13: WP-C01 | K13: PP-C01
A14: C02 | B14: Site C - sheltered lagoon | C14: Lagoon edge | D14: 46095 | E14: Avicennia marina | F14: Wild propagules, partner nursery | G14: 400 | H14: 1.5 | I14: Partner group 3 | J14: WP-C02 | K14: PP-C02
A15: C03 | B15: Site C - sheltered lagoon | C15: Inner flat | D15: 46095 | E15: Avicennia marina | F15: Wild propagules, partner nursery | G15: 400 | H15: 1.5 | I15: Partner group 3 | J15: WP-C03 | K15: PP-C03
A16: C04 | B16: Site C - sheltered lagoon | C16: Inner flat | D16: 46095 | E16: Avicennia marina | F16: Wild propagules, partner nursery | G16: 400 | H16: 1.5 | I16: Partner group 3 | J16: WP-C04 | K16: PP-C04

Sheet Monitoring
A1: Monitoring census
A2: One row per plot visit. Yellow = input, grey = formula. Illustrative data with eight deliberate entry errors for the checks to catch.
A4: Visit ID | B4: Plot ID | C4: Visit date | D4: Visit type | E4: Observer | F4: Alive | G4: Dead | H4: Missing | I4: Main cause of loss | J4: Mean height (cm) | K4: Replanted this visit | L4: Notes | M4: Site | N4: Planted on | O4: Months since planting | P4: Census month | Q4: Seedlings planted | R4: Replanted before this visit | S4: Expected total | T4: Survival (all planted) | U4: Stocking (vs design) | V4: Previous visit | W4: Alive at previous visit | X4: Replanted since previous | Y4: QA flags | Z4: QA issues
A5: V001 | B5: A01 | C5: 45979 | D5: Census | E5: FS-1 (field staff) | F5: 455 | G5: 30 | H5: 15 | I5: Wave/scour | J5: 48 | K5: 0 | M5: =IF($B5="","",IFERROR(INDEX(Planting_Log!$B$5:$B$60,MATCH($B5,Planting_Log!$A$5:$A$60,0)),"")) -> Site A - seaward fringe | N5: =IF($B5="","",IFERROR(INDEX(Planting_Log!$D$5:$D$60,MATCH($B5,Planting_Log!$A$5:$A$60,0)),"")) -> 45948 | O5: =IF(OR(N5="",C5=""),"",ROUND((C5-N5)/30.44,1)) -> 1 | P5: =IF(O5="","",IF(O5<2,1,IF(O5<4.5,3,IF(O5<7.5,6,IF(O5<10.5,9,12))))) -> 1 | Q5: =IF($B5="","",IFERROR(INDEX(Planting_Log!$G$5:$G$60,MATCH($B5,Planting_Log!$A$5:$A$60,0)),"")) -> 500 | R5: =IF($B5="","",SUMIFS($K$5:$K$200,$B$5:$B$200,$B5,$C$5:$C$200,"<"&$C5)) -> 0 | S5: =IF(Q5="","",Q5+R5) -> 500 | T5: =IF(OR(S5="",S5=0),"",F5/S5) -> 0.91 | U5: =IF(OR(Q5="",Q5=0),"",F5/Q5) -> 0.91 | V5: =IF($B5="","",IF(COUNTIFS($B$5:$B$200,$B5,$C$5:$C$200,"<"&$C5)=0,"",SUMPRODUCT(MAX(($B$5:$B$200=$B5)*($C$5:$C$200<$C5)*$C$5:$C$200)))) | W5: =IF(V5="","",SUMIFS($F$5:$F$200,$B$5:$B$200,$B5,$C$5:$C$200,V5)) | X5: =IF($B5="","",IF(V5="",0,SUMIFS($K$5:$K$200,$B$5:$B$200,$B5,$C$5:$C$200,">="&V5,$C$5:$C$200,"<"&$C5))) -> 0 | Y5: =IF($B5="","",MID(IF(M5="","; Unknown plot","")&IF(N5="","",IF(C5<N5,"; Visit before planting",""))&IF(S5="","",IF(F5+G5+H5<>S5,"; Count mismatch",""))&IF(W5="","",IF(F5>W5+X5,"; Alive rose without replanting",""))&IF(COUNTIFS($B$5:$B$200,$B5,$C$5:$C$200,$C5)>1,"; Duplicate visit","")&IF(J5="","",IF(OR(J5<HMin,J5>HMax),"; Height out of range",""))&IF(E5="","; No observer","")&IF(G5+H5>0,IF(I5="","; Loss without cause",""),""),3,300)) | Z5: =IF($B5="","",IF(Y5="",0,1+LEN(Y5)-LEN(SUBSTITUTE(Y5,";","")))) -> 0
A6: V002 | B6: A01 | C6: 46039 | D6: Census | E6: FS-1 (field staff) | F6: 360 | G6: 90 | H6: 50 | I6: Wave/scour | J6: 55 | K6: 0 | M6: =IF($B6="","",IFERROR(INDEX(Planting_Log!$B$5:$B$60,MATCH($B6,Planting_Log!$A$5:$A$60,0)),"")) -> Site A - seaward fringe | N6: =IF($B6="","",IFERROR(INDEX(Planting_Log!$D$5:$D$60,MATCH($B6,Planting_Log!$A$5:$A$60,0)),"")) -> 45948 | O6: =IF(OR(N6="",C6=""),"",ROUND((C6-N6)/30.44,1)) -> 3 | P6: =IF(O6="","",IF(O6<2,1,IF(O6<4.5,3,IF(O6<7.5,6,IF(O6<10.5,9,12))))) -> 3 | Q6: =IF($B6="","",IFERROR(INDEX(Planting_Log!$G$5:$G$60,MATCH($B6,Planting_Log!$A$5:$A$60,0)),"")) -> 500 | R6: =IF($B6="","",SUMIFS($K$5:$K$200,$B$5:$B$200,$B6,$C$5:$C$200,"<"&$C6)) -> 0 | S6: =IF(Q6="","",Q6+R6) -> 500 | T6: =IF(OR(S6="",S6=0),"",F6/S6) -> 0.72 | U6: =IF(OR(Q6="",Q6=0),"",F6/Q6) -> 0.72 | V6: =IF($B6="","",IF(COUNTIFS($B$5:$B$200,$B6,$C$5:$C$200,"<"&$C6)=0,"",SUMPRODUCT(MAX(($B$5:$B$200=$B6)*($C$5:$C$200<$C6)*$C$5:$C$200)))) -> 45979 | W6: =IF(V6="","",SUMIFS($F$5:$F$200,$B$5:$B$200,$B6,$C$5:$C$200,V6)) -> 455 | X6: =IF($B6="","",IF(V6="",0,SUMIFS($K$5:$K$200,$B$5:$B$200,$B6,$C$5:$C$200,">="&V6,$C$5:$C$200,"<"&$C6))) -> 0 | Y6: =IF($B6="","",MID(IF(M6="","; Unknown plot","")&IF(N6="","",IF(C6<N6,"; Visit before planting",""))&IF(S6="","",IF(F6+G6+H6<>S6,"; Count mismatch",""))&IF(W6="","",IF(F6>W6+X6,"; Alive rose without replanting",""))&IF(COUNTIFS($B$5:$B$200,$B6,$C$5:$C$200,$C6)>1,"; Duplicate visit","")&IF(J6="","",IF(OR(J6<HMin,J6>HMax),"; Height out of range",""))&IF(E6="","; No observer","")&IF(G6+H6>0,IF(I6="","; Loss without cause",""),""),3,300)) | Z6: =IF($B6="","",IF(Y6="",0,1+LEN(Y6)-LEN(SUBSTITUTE(Y6,";","")))) -> 0
A7: V003 | B7: A01 | C7: 46130 | D7: Census | E7: FS-1 (field staff) | F7: 290 | G7: 130 | H7: 80 | I7: Wave/scour | J7: 64 | K7: 0 | L7: Scour on the seaward edge | M7: =IF($B7="","",IFERROR(INDEX(Planting_Log!$B$5:$B$60,MATCH($B7,Planting_Log!$A$5:$A$60,0)),"")) -> Site A - seaward fringe | N7: =IF($B7="","",IFERROR(INDEX(Planting_Log!$D$5:$D$60,MATCH($B7,Planting_Log!$A$5:$A$60,0)),"")) -> 45948 | O7: =IF(OR(N7="",C7=""),"",ROUND((C7-N7)/30.44,1)) -> 6 | P7: =IF(O7="","",IF(O7<2,1,IF(O7<4.5,3,IF(O7<7.5,6,IF(O7<10.5,9,12))))) -> 6 | Q7: =IF($B7="","",IFERROR(INDEX(Planting_Log!$G$5:$G$60,MATCH($B7,Planting_Log!$A$5:$A$60,0)),"")) -> 500 | R7: =IF($B7="","",SUMIFS($K$5:$K$200,$B$5:$B$200,$B7,$C$5:$C$200,"<"&$C7)) -> 0 | S7: =IF(Q7="","",Q7+R7) -> 500 | T7: =IF(OR(S7="",S7=0),"",F7/S7) -> 0.58 | U7: =IF(OR(Q7="",Q7=0),"",F7/Q7) -> 0.58 | V7: =IF($B7="","",IF(COUNTIFS($B$5:$B$200,$B7,$C$5:$C$200,"<"&$C7)=0,"",SUMPRODUCT(MAX(($B$5:$B$200=$B7)*($C$5:$C$200<$C7)*$C$5:$C$200)))) -> 46039 | W7: =IF(V7="","",SUMIFS($F$5:$F$200,$B$5:$B$200,$B7,$C$5:$C$200,V7)) -> 360 | X7: =IF($B7="","",IF(V7="",0,SUMIFS($K$5:$K$200,$B$5:$B$200,$B7,$C$5:$C$200,">="&V7,$C$5:$C$200,"<"&$C7))) -> 0 | Y7: =IF($B7="","",MID(IF(M7="","; Unknown plot","")&IF(N7="","",IF(C7<N7,"; Visit before planting",""))&IF(S7="","",IF(F7+G7+H7<>S7,"; Count mismatch",""))&IF(W7="","",IF(F7>W7+X7,"; Alive rose without replanting",""))&IF(COUNTIFS($B$5:$B$200,$B7,$C$5:$C$200,$C7)>1,"; Duplicate visit","")&IF(J7="","",IF(OR(J7<HMin,J7>HMax),"; Height out of range",""))&IF(E7="","; No observer","")&IF(G7+H7>0,IF(I7="","; Loss without cause",""),""),3,300)) | Z7: =IF($B7="","",IF(Y7="",0,1+LEN(Y7)-LEN(SUBSTITUTE(Y7,";","")))) -> 0
A8: V004 | B8: A01 | C8: 46158 | D8: Replanting | E8: PL-1 (partner lead) | F8: 286 | G8: 132 | H8: 82 | I8: Wave/scour | J8: 66 | K8: 115 | L8: Replanted with stakes | M8: =IF($B8="","",IFERROR(INDEX(Planting_Log!$B$5:$B$60,MATCH($B8,Planting_Log!$A$5:$A$60,0)),"")) -> Site A - seaward fringe | N8: =IF($B8="","",IFERROR(INDEX(Planting_Log!$D$5:$D$60,MATCH($B8,Planting_Log!$A$5:$A$60,0)),"")) -> 45948 | O8: =IF(OR(N8="",C8=""),"",ROUND((C8-N8)/30.44,1)) -> 6.9 | P8: =IF(O8="","",IF(O8<2,1,IF(O8<4.5,3,IF(O8<7.5,6,IF(O8<10.5,9,12))))) -> 6 | Q8: =IF($B8="","",IFERROR(INDEX(Planting_Log!$G$5:$G$60,MATCH($B8,Planting_Log!$A$5:$A$60,0)),"")) -> 500 | R8: =IF($B8="","",SUMIFS($K$5:$K$200,$B$5:$B$200,$B8,$C$5:$C$200,"<"&$C8)) -> 0 | S8: =IF(Q8="","",Q8+R8) -> 500 | T8: =IF(OR(S8="",S8=0),"",F8/S8) -> 0.572 | U8: =IF(OR(Q8="",Q8=0),"",F8/Q8) -> 0.572 | V8: =IF($B8="","",IF(COUNTIFS($B$5:$B$200,$B8,$C$5:$C$200,"<"&$C8)=0,"",SUMPRODUCT(MAX(($B$5:$B$200=$B8)*($C$5:$C$200<$C8)*$C$5:$C$200)))) -> 46130 | W8: =IF(V8="","",SUMIFS($F$5:$F$200,$B$5:$B$200,$B8,$C$5:$C$200,V8)) -> 290 | X8: =IF($B8="","",IF(V8="",0,SUMIFS($K$5:$K$200,$B$5:$B$200,$B8,$C$5:$C$200,">="&V8,$C$5:$C$200,"<"&$C8))) -> 0 | Y8: =IF($B8="","",MID(IF(M8="","; Unknown plot","")&IF(N8="","",IF(C8<N8,"; Visit before planting",""))&IF(S8="","",IF(F8+G8+H8<>S8,"; Count mismatch",""))&IF(W8="","",IF(F8>W8+X8,"; Alive rose without replanting",""))&IF(COUNTIFS($B$5:$B$200,$B8,$C$5:$C$200,$C8)>1,"; Duplicate visit","")&IF(J8="","",IF(OR(J8<HMin,J8>HMax),"; Height out of range",""))&IF(E8="","; No observer","")&IF(G8+H8>0,IF(I8="","; Loss without cause",""),""),3,300)) | Z8: =IF($B8="","",IF(Y8="",0,1+LEN(Y8)-LEN(SUBSTITUTE(Y8,";","")))) -> 0
A9: V005 | B9: A02 | C9: 45979 | D9: Census | E9: FS-1 (field staff) | F9: 440 | G9: 40 | H9: 20 | I9: Wave/scour | J9: 47 | K9: 0 | M9: =IF($B9="","",IFERROR(INDEX(Planting_Log!$B$5:$B$60,MATCH($B9,Planting_Log!$A$5:$A$60,0)),"")) -> Site A - seaward fringe | N9: =IF($B9="","",IFERROR(INDEX(Planting_Log!$D$5:$D$60,MATCH($B9,Planting_Log!$A$5:$A$60,0)),"")) -> 45948 | O9: =IF(OR(N9="",C9=""),"",ROUND((C9-N9)/30.44,1)) -> 1 | P9: =IF(O9="","",IF(O9<2,1,IF(O9<4.5,3,IF(O9<7.5,6,IF(O9<10.5,9,12))))) -> 1 | Q9: =IF($B9="","",IFERROR(INDEX(Planting_Log!$G$5:$G$60,MATCH($B9,Planting_Log!$A$5:$A$60,0)),"")) -> 500 | R9: =IF($B9="","",SUMIFS($K$5:$K$200,$B$5:$B$200,$B9,$C$5:$C$200,"<"&$C9)) -> 0 | S9: =IF(Q9="","",Q9+R9) -> 500 | T9: =IF(OR(S9="",S9=0),"",F9/S9) -> 0.88 | U9: =IF(OR(Q9="",Q9=0),"",F9/Q9) -> 0.88 | V9: =IF($B9="","",IF(COUNTIFS($B$5:$B$200,$B9,$C$5:$C$200,"<"&$C9)=0,"",SUMPRODUCT(MAX(($B$5:$B$200=$B9)*($C$5:$C$200<$C9)*$C$5:$C$200)))) | W9: =IF(V9="","",SUMIFS($F$5:$F$200,$B$5:$B$200,$B9,$C$5:$C$200,V9)) | X9: =IF($B9="","",IF(V9="",0,SUMIFS($K$5:$K$200,$B$5:$B$200,$B9,$C$5:$C$200,">="&V9,$C$5:$C$200,"<"&$C9))) -> 0 | Y9: =IF($B9="","",MID(IF(M9="","; Unknown plot","")&IF(N9="","",IF(C9<N9,"; Visit before planting",""))&IF(S9="","",IF(F9+G9+H9<>S9,"; Count mismatch",""))&IF(W9="","",IF(F9>W9+X9,"; Alive rose without replanting",""))&IF(COUNTIFS($B$5:$B$200,$B9,$C$5:$C$200,$C9)>1,"; Duplicate visit","")&IF(J9="","",IF(OR(J9<HMin,J9>HMax),"; Height out of range",""))&IF(E9="","; No observer","")&IF(G9+H9>0,IF(I9="","; Loss without cause",""),""),3,300)) | Z9: =IF($B9="","",IF(Y9="",0,1+LEN(Y9)-LEN(SUBSTITUTE(Y9,";","")))) -> 0
A10: V006 | B10: A02 | C10: 46039 | D10: Census | E10: FS-1 (field staff) | F10: 330 | G10: 110 | H10: 60 | I10: Barnacles | J10: 54 | K10: 0 | M10: =IF($B10="","",IFERROR(INDEX(Planting_Log!$B$5:$B$60,MATCH($B10,Planting_Log!$A$5:$A$60,0)),"")) -> Site A - seaward fringe | N10: =IF($B10="","",IFERROR(INDEX(Planting_Log!$D$5:$D$60,MATCH($B10,Planting_Log!$A$5:$A$60,0)),"")) -> 45948 | O10: =IF(OR(N10="",C10=""),"",ROUND((C10-N10)/30.44,1)) -> 3 | P10: =IF(O10="","",IF(O10<2,1,IF(O10<4.5,3,IF(O10<7.5,6,IF(O10<10.5,9,12))))) -> 3 | Q10: =IF($B10="","",IFERROR(INDEX(Planting_Log!$G$5:$G$60,MATCH($B10,Planting_Log!$A$5:$A$60,0)),"")) -> 500 | R10: =IF($B10="","",SUMIFS($K$5:$K$200,$B$5:$B$200,$B10,$C$5:$C$200,"<"&$C10)) -> 0 | S10: =IF(Q10="","",Q10+R10) -> 500 | T10: =IF(OR(S10="",S10=0),"",F10/S10) -> 0.66 | U10: =IF(OR(Q10="",Q10=0),"",F10/Q10) -> 0.66 | V10: =IF($B10="","",IF(COUNTIFS($B$5:$B$200,$B10,$C$5:$C$200,"<"&$C10)=0,"",SUMPRODUCT(MAX(($B$5:$B$200=$B10)*($C$5:$C$200<$C10)*$C$5:$C$200)))) -> 45979 | W10: =IF(V10="","",SUMIFS($F$5:$F$200,$B$5:$B$200,$B10,$C$5:$C$200,V10)) -> 440 | X10: =IF($B10="","",IF(V10="",0,SUMIFS($K$5:$K$200,$B$5:$B$200,$B10,$C$5:$C$200,">="&V10,$C$5:$C$200,"<"&$C10))) -> 0 | Y10: =IF($B10="","",MID(IF(M10="","; Unknown plot","")&IF(N10="","",IF(C10<N10,"; Visit before planting",""))&IF(S10="","",IF(F10+G10+H10<>S10,"; Count mismatch",""))&IF(W10="","",IF(F10>W10+X10,"; Alive rose without replanting",""))&IF(COUNTIFS($B$5:$B$200,$B10,$C$5:$C$200,$C10)>1,"; Duplicate visit","")&IF(J10="","",IF(OR(J10<HMin,J10>HMax),"; Height out of range",""))&IF(E10="","; No observer","")&IF(G10+H10>0,IF(I10="","; Loss without cause",""),""),3,300)) | Z10: =IF($B10="","",IF(Y10="",0,1+LEN(Y10)-LEN(SUBSTITUTE(Y10,";","")))) -> 0
A11: V007 | B11: A02 | C11: 46130 | D11: Census | E11: FS-1 (field staff) | F11: 245 | G11: 150 | H11: 105 | I11: Barnacles | J11: 62 | K11: 0 | L11: Heavy barnacle load | M11: =IF($B11="","",IFERROR(INDEX(Planting_Log!$B$5:$B$60,MATCH($B11,Planting_Log!$A$5:$A$60,0)),"")) -> Site A - seaward fringe | N11: =IF($B11="","",IFERROR(INDEX(Planting_Log!$D$5:$D$60,MATCH($B11,Planting_Log!$A$5:$A$60,0)),"")) -> 45948 | O11: =IF(OR(N11="",C11=""),"",ROUND((C11-N11)/30.44,1)) -> 6 | P11: =IF(O11="","",IF(O11<2,1,IF(O11<4.5,3,IF(O11<7.5,6,IF(O11<10.5,9,12))))) -> 6 | Q11: =IF($B11="","",IFERROR(INDEX(Planting_Log!$G$5:$G$60,MATCH($B11,Planting_Log!$A$5:$A$60,0)),"")) -> 500 | R11: =IF($B11="","",SUMIFS($K$5:$K$200,$B$5:$B$200,$B11,$C$5:$C$200,"<"&$C11)) -> 0 | S11: =IF(Q11="","",Q11+R11) -> 500 | T11: =IF(OR(S11="",S11=0),"",F11/S11) -> 0.49 | U11: =IF(OR(Q11="",Q11=0),"",F11/Q11) -> 0.49 | V11: =IF($B11="","",IF(COUNTIFS($B$5:$B$200,$B11,$C$5:$C$200,"<"&$C11)=0,"",SUMPRODUCT(MAX(($B$5:$B$200=$B11)*($C$5:$C$200<$C11)*$C$5:$C$200)))) -> 46039 | W11: =IF(V11="","",SUMIFS($F$5:$F$200,$B$5:$B$200,$B11,$C$5:$C$200,V11)) -> 330 | X11: =IF($B11="","",IF(V11="",0,SUMIFS($K$5:$K$200,$B$5:$B$200,$B11,$C$5:$C$200,">="&V11,$C$5:$C$200,"<"&$C11))) -> 0 | Y11: =IF($B11="","",MID(IF(M11="","; Unknown plot","")&IF(N11="","",IF(C11<N11,"; Visit before planting",""))&IF(S11="","",IF(F11+G11+H11<>S11,"; Count mismatch",""))&IF(W11="","",IF(F11>W11+X11,"; Alive rose without replanting",""))&IF(COUNTIFS($B$5:$B$200,$B11,$C$5:$C$200,$C11)>1,"; Duplicate visit","")&IF(J11="","",IF(OR(J11<HMin,J11>HMax),"; Height out of range",""))&IF(E11="","; No observer","")&IF(G11+H11>0,IF(I11="","; Loss without cause",""),""),3,300)) | Z11: =IF($B11="","",IF(Y11="",0,1+LEN(Y11)-LEN(SUBSTITUTE(Y11,";","")))) -> 0
A12: V008 | B12: A02 | C12: 46158 | D12: Replanting | E12: PL-1 (partner lead) | F12: 243 | G12: 152 | H12: 105 | I12: Barnacles | J12: 63 | K12: 157 | L12: Stems cleaned before replanting | M12: =IF($B12="","",IFERROR(INDEX(Planting_Log!$B$5:$B$60,MATCH($B12,Planting_Log!$A$5:$A$60,0)),"")) -> Site A - seaward fringe | N12: =IF($B12="","",IFERROR(INDEX(Planting_Log!$D$5:$D$60,MATCH($B12,Planting_Log!$A$5:$A$60,0)),"")) -> 45948 | O12: =IF(OR(N12="",C12=""),"",ROUND((C12-N12)/30.44,1)) -> 6.9 | P12: =IF(O12="","",IF(O12<2,1,IF(O12<4.5,3,IF(O12<7.5,6,IF(O12<10.5,9,12))))) -> 6 | Q12: =IF($B12="","",IFERROR(INDEX(Planting_Log!$G$5:$G$60,MATCH($B12,Planting_Log!$A$5:$A$60,0)),"")) -> 500 | R12: =IF($B12="","",SUMIFS($K$5:$K$200,$B$5:$B$200,$B12,$C$5:$C$200,"<"&$C12)) -> 0 | S12: =IF(Q12="","",Q12+R12) -> 500 | T12: =IF(OR(S12="",S12=0),"",F12/S12) -> 0.486 | U12: =IF(OR(Q12="",Q12=0),"",F12/Q12) -> 0.486 | V12: =IF($B12="","",IF(COUNTIFS($B$5:$B$200,$B12,$C$5:$C$200,"<"&$C12)=0,"",SUMPRODUCT(MAX(($B$5:$B$200=$B12)*($C$5:$C$200<$C12)*$C$5:$C$200)))) -> 46130 | W12: =IF(V12="","",SUMIFS($F$5:$F$200,$B$5:$B$200,$B12,$C$5:$C$200,V12)) -> 245 | X12: =IF($B12="","",IF(V12="",0,SUMIFS($K$5:$K$200,$B$5:$B$200,$B12,$C$5:$C$200,">="&V12,$C$5:$C$200,"<"&$C12))) -> 0 | Y12: =IF($B12="","",MID(IF(M12="","; Unknown plot","")&IF(N12="","",IF(C12<N12,"; Visit before planting",""))&IF(S12="","",IF(F12+G12+H12<>S12,"; Count mismatch",""))&IF(W12="","",IF(F12>W12+X12,"; Alive rose without replanting",""))&IF(COUNTIFS($B$5:$B$200,$B12,$C$5:$C$200,$C12)>1,"; Duplicate visit","")&IF(J12="","",IF(OR(J12<HMin,J12>HMax),"; Height out of range",""))&IF(E12="","; No observer","")&IF(G12+H12>0,IF(I12="","; Loss without cause",""),""),3,300)) | Z12: =IF($B12="","",IF(Y12="",0,1+LEN(Y12)-LEN(SUBSTITUTE(Y12,";","")))) -> 0
A13: V009 | B13: A02 | C13: 46221 | D13: Follow-up | E13: FS-2 (field staff) | F13: 372 | G13: 170 | H13: 115 | I13: Barnacles | J13: 70 | K13: 0 | L13: Replanted seedlings mostly alive | M13: =IF($B13="","",IFERROR(INDEX(Planting_Log!$B$5:$B$60,MATCH($B13,Planting_Log!$A$5:$A$60,0)),"")) -> Site A - seaward fringe | N13: =IF($B13="","",IFERROR(INDEX(Planting_Log!$D$5:$D$60,MATCH($B13,Planting_Log!$A$5:$A$60,0)),"")) -> 45948 | O13: =IF(OR(N13="",C13=""),"",ROUND((C13-N13)/30.44,1)) -> 9 | P13: =IF(O13="","",IF(O13<2,1,IF(O13<4.5,3,IF(O13<7.5,6,IF(O13<10.5,9,12))))) -> 9 | Q13: =IF($B13="","",IFERROR(INDEX(Planting_Log!$G$5:$G$60,MATCH($B13,Planting_Log!$A$5:$A$60,0)),"")) -> 500 | R13: =IF($B13="","",SUMIFS($K$5:$K$200,$B$5:$B$200,$B13,$C$5:$C$200,"<"&$C13)) -> 157 | S13: =IF(Q13="","",Q13+R13) -> 657 | T13: =IF(OR(S13="",S13=0),"",F13/S13) -> 0.56621005 | U13: =IF(OR(Q13="",Q13=0),"",F13/Q13) -> 0.744 | V13: =IF($B13="","",IF(COUNTIFS($B$5:$B$200,$B13,$C$5:$C$200,"<"&$C13)=0,"",SUMPRODUCT(MAX(($B$5:$B$200=$B13)*($C$5:$C$200<$C13)*$C$5:$C$200)))) -> 46158 | W13: =IF(V13="","",SUMIFS($F$5:$F$200,$B$5:$B$200,$B13,$C$5:$C$200,V13)) -> 243 | X13: =IF($B13="","",IF(V13="",0,SUMIFS($K$5:$K$200,$B$5:$B$200,$B13,$C$5:$C$200,">="&V13,$C$5:$C$200,"<"&$C13))) -> 157 | Y13: =IF($B13="","",MID(IF(M13="","; Unknown plot","")&IF(N13="","",IF(C13<N13,"; Visit before planting",""))&IF(S13="","",IF(F13+G13+H13<>S13,"; Count mismatch",""))&IF(W13="","",IF(F13>W13+X13,"; Alive rose without replanting",""))&IF(COUNTIFS($B$5:$B$200,$B13,$C$5:$C$200,$C13)>1,"; Duplicate visit","")&IF(J13="","",IF(OR(J13<HMin,J13>HMax),"; Height out of range",""))&IF(E13="","; No observer","")&IF(G13+H13>0,IF(I13="","; Loss without cause",""),""),3,300)) | Z13: =IF($B13="","",IF(Y13="",0,1+LEN(Y13)-LEN(SUBSTITUTE(Y13,";","")))) -> 0
A14: V010 | B14: A03 | C14: 45979 | D14: Census | E14: FS-2 (field staff) | F14: 470 | G14: 20 | H14: 10 | I14: Sediment burial | J14: 49 | K14: 0 | M14: =IF($B14="","",IFERROR(INDEX(Planting_Log!$B$5:$B$60,MATCH($B14,Planting_Log!$A$5:$A$60,0)),"")) -> Site A - seaward fringe | N14: =IF($B14="","",IFERROR(INDEX(Planting_Log!$D$5:$D$60,MATCH($B14,Planting_Log!$A$5:$A$60,0)),"")) -> 45948 | O14: =IF(OR(N14="",C14=""),"",ROUND((C14-N14)/30.44,1)) -> 1 | P14: =IF(O14="","",IF(O14<2,1,IF(O14<4.5,3,IF(O14<7.5,6,IF(O14<10.5,9,12))))) -> 1 | Q14: =IF($B14="","",IFERROR(INDEX(Planting_Log!$G$5:$G$60,MATCH($B14,Planting_Log!$A$5:$A$60,0)),"")) -> 500 | R14: =IF($B14="","",SUMIFS($K$5:$K$200,$B$5:$B$200,$B14,$C$5:$C$200,"<"&$C14)) -> 0 | S14: =IF(Q14="","",Q14+R14) -> 500 | T14: =IF(OR(S14="",S14=0),"",F14/S14) -> 0.94 | U14: =IF(OR(Q14="",Q14=0),"",F14/Q14) -> 0.94 | V14: =IF($B14="","",IF(COUNTIFS($B$5:$B$200,$B14,$C$5:$C$200,"<"&$C14)=0,"",SUMPRODUCT(MAX(($B$5:$B$200=$B14)*($C$5:$C$200<$C14)*$C$5:$C$200)))) | W14: =IF(V14="","",SUMIFS($F$5:$F$200,$B$5:$B$200,$B14,$C$5:$C$200,V14)) | X14: =IF($B14="","",IF(V14="",0,SUMIFS($K$5:$K$200,$B$5:$B$200,$B14,$C$5:$C$200,">="&V14,$C$5:$C$200,"<"&$C14))) -> 0 | Y14: =IF($B14="","",MID(IF(M14="","; Unknown plot","")&IF(N14="","",IF(C14<N14,"; Visit before planting",""))&IF(S14="","",IF(F14+G14+H14<>S14,"; Count mismatch",""))&IF(W14="","",IF(F14>W14+X14,"; Alive rose without replanting",""))&IF(COUNTIFS($B$5:$B$200,$B14,$C$5:$C$200,$C14)>1,"; Duplicate visit","")&IF(J14="","",IF(OR(J14<HMin,J14>HMax),"; Height out of range",""))&IF(E14="","; No observer","")&IF(G14+H14>0,IF(I14="","; Loss without cause",""),""),3,300)) | Z14: =IF($B14="","",IF(Y14="",0,1+LEN(Y14)-LEN(SUBSTITUTE(Y14,";","")))) -> 0
A15: V011 | B15: A03 | C15: 46039 | D15: Census | E15: FS-2 (field staff) | F15: 410 | G15: 60 | H15: 50 | I15: Sediment burial | J15: 56 | K15: 0 | L15: Tally sheet re-added on the boat | M15: =IF($B15="","",IFERROR(INDEX(Planting_Log!$B$5:$B$60,MATCH($B15,Planting_Log!$A$5:$A$60,0)),"")) -> Site A - seaward fringe | N15: =IF($B15="","",IFERROR(INDEX(Planting_Log!$D$5:$D$60,MATCH($B15,Planting_Log!$A$5:$A$60,0)),"")) -> 45948 | O15: =IF(OR(N15="",C15=""),"",ROUND((C15-N15)/30.44,1)) -> 3 | P15: =IF(O15="","",IF(O15<2,1,IF(O15<4.5,3,IF(O15<7.5,6,IF(O15<10.5,9,12))))) -> 3 | Q15: =IF($B15="","",IFERROR(INDEX(Planting_Log!$G$5:$G$60,MATCH($B15,Planting_Log!$A$5:$A$60,0)),"")) -> 500 | R15: =IF($B15="","",SUMIFS($K$5:$K$200,$B$5:$B$200,$B15,$C$5:$C$200,"<"&$C15)) -> 0 | S15: =IF(Q15="","",Q15+R15) -> 500 | T15: =IF(OR(S15="",S15=0),"",F15/S15) -> 0.82 | U15: =IF(OR(Q15="",Q15=0),"",F15/Q15) -> 0.82 | V15: =IF($B15="","",IF(COUNTIFS($B$5:$B$200,$B15,$C$5:$C$200,"<"&$C15)=0,"",SUMPRODUCT(MAX(($B$5:$B$200=$B15)*($C$5:$C$200<$C15)*$C$5:$C$200)))) -> 45979 | W15: =IF(V15="","",SUMIFS($F$5:$F$200,$B$5:$B$200,$B15,$C$5:$C$200,V15)) -> 470 | X15: =IF($B15="","",IF(V15="",0,SUMIFS($K$5:$K$200,$B$5:$B$200,$B15,$C$5:$C$200,">="&V15,$C$5:$C$200,"<"&$C15))) -> 0 | Y15: =IF($B15="","",MID(IF(M15="","; Unknown plot","")&IF(N15="","",IF(C15<N15,"; Visit before planting",""))&IF(S15="","",IF(F15+G15+H15<>S15,"; Count mismatch",""))&IF(W15="","",IF(F15>W15+X15,"; Alive rose without replanting",""))&IF(COUNTIFS($B$5:$B$200,$B15,$C$5:$C$200,$C15)>1,"; Duplicate visit","")&IF(J15="","",IF(OR(J15<HMin,J15>HMax),"; Height out of range",""))&IF(E15="","; No observer","")&IF(G15+H15>0,IF(I15="","; Loss without cause",""),""),3,300)) -> Count mismatch | Z15: =IF($B15="","",IF(Y15="",0,1+LEN(Y15)-LEN(SUBSTITUTE(Y15,";","")))) -> 1
A16: V012 | B16: A03 | C16: 46130 | D16: Census | E16: FS-2 (field staff) | F16: 365 | G16: 95 | H16: 40 | I16: Barnacles | J16: 66 | K16: 0 | M16: =IF($B16="","",IFERROR(INDEX(Planting_Log!$B$5:$B$60,MATCH($B16,Planting_Log!$A$5:$A$60,0)),"")) -> Site A - seaward fringe | N16: =IF($B16="","",IFERROR(INDEX(Planting_Log!$D$5:$D$60,MATCH($B16,Planting_Log!$A$5:$A$60,0)),"")) -> 45948 | O16: =IF(OR(N16="",C16=""),"",ROUND((C16-N16)/30.44,1)) -> 6 | P16: =IF(O16="","",IF(O16<2,1,IF(O16<4.5,3,IF(O16<7.5,6,IF(O16<10.5,9,12))))) -> 6 | Q16: =IF($B16="","",IFERROR(INDEX(Planting_Log!$G$5:$G$60,MATCH($B16,Planting_Log!$A$5:$A$60,0)),"")) -> 500 | R16: =IF($B16="","",SUMIFS($K$5:$K$200,$B$5:$B$200,$B16,$C$5:$C$200,"<"&$C16)) -> 0 | S16: =IF(Q16="","",Q16+R16) -> 500 | T16: =IF(OR(S16="",S16=0),"",F16/S16) -> 0.73 | U16: =IF(OR(Q16="",Q16=0),"",F16/Q16) -> 0.73 | V16: =IF($B16="","",IF(COUNTIFS($B$5:$B$200,$B16,$C$5:$C$200,"<"&$C16)=0,"",SUMPRODUCT(MAX(($B$5:$B$200=$B16)*($C$5:$C$200<$C16)*$C$5:$C$200)))) -> 46039 | W16: =IF(V16="","",SUMIFS($F$5:$F$200,$B$5:$B$200,$B16,$C$5:$C$200,V16)) -> 410 | X16: =IF($B16="","",IF(V16="",0,SUMIFS($K$5:$K$200,$B$5:$B$200,$B16,$C$5:$C$200,">="&V16,$C$5:$C$200,"<"&$C16))) -> 0 | Y16: =IF($B16="","",MID(IF(M16="","; Unknown plot","")&IF(N16="","",IF(C16<N16,"; Visit before planting",""))&IF(S16="","",IF(F16+G16+H16<>S16,"; Count mismatch",""))&IF(W16="","",IF(F16>W16+X16,"; Alive rose without replanting",""))&IF(COUNTIFS($B$5:$B$200,$B16,$C$5:$C$200,$C16)>1,"; Duplicate visit","")&IF(J16="","",IF(OR(J16<HMin,J16>HMax),"; Height out of range",""))&IF(E16="","; No observer","")&IF(G16+H16>0,IF(I16="","; Loss without cause",""),""),3,300)) | Z16: =IF($B16="","",IF(Y16="",0,1+LEN(Y16)-LEN(SUBSTITUTE(Y16,";","")))) -> 0
A17: V013 | B17: A04 | C17: 45980 | D17: Census | E17: FS-2 (field staff) | F17: 425 | G17: 15 | H17: 10 | I17: Wave/scour | J17: 48 | K17: 0 | M17: =IF($B17="","",IFERROR(INDEX(Planting_Log!$B$5:$B$60,MATCH($B17,Planting_Log!$A$5:$A$60,0)),"")) -> Site A - seaward fringe | N17: =IF($B17="","",IFERROR(INDEX(Planting_Log!$D$5:$D$60,MATCH($B17,Planting_Log!$A$5:$A$60,0)),"")) -> 45949 | O17: =IF(OR(N17="",C17=""),"",ROUND((C17-N17)/30.44,1)) -> 1 | P17: =IF(O17="","",IF(O17<2,1,IF(O17<4.5,3,IF(O17<7.5,6,IF(O17<10.5,9,12))))) -> 1 | Q17: =IF($B17="","",IFERROR(INDEX(Planting_Log!$G$5:$G$60,MATCH($B17,Planting_Log!$A$5:$A$60,0)),"")) -> 450 | R17: =IF($B17="","",SUMIFS($K$5:$K$200,$B$5:$B$200,$B17,$C$5:$C$200,"<"&$C17)) -> 0 | S17: =IF(Q17="","",Q17+R17) -> 450 | T17: =IF(OR(S17="",S17=0),"",F17/S17) -> 0.94444444 | U17: =IF(OR(Q17="",Q17=0),"",F17/Q17) -> 0.94444444 | V17: =IF($B17="","",IF(COUNTIFS($B$5:$B$200,$B17,$C$5:$C$200,"<"&$C17)=0,"",SUMPRODUCT(MAX(($B$5:$B$200=$B17)*($C$5:$C$200<$C17)*$C$5:$C$200)))) | W17: =IF(V17="","",SUMIFS($F$5:$F$200,$B$5:$B$200,$B17,$C$5:$C$200,V17)) | X17: =IF($B17="","",IF(V17="",0,SUMIFS($K$5:$K$200,$B$5:$B$200,$B17,$C$5:$C$200,">="&V17,$C$5:$C$200,"<"&$C17))) -> 0 | Y17: =IF($B17="","",MID(IF(M17="","; Unknown plot","")&IF(N17="","",IF(C17<N17,"; Visit before planting",""))&IF(S17="","",IF(F17+G17+H17<>S17,"; Count mismatch",""))&IF(W17="","",IF(F17>W17+X17,"; Alive rose without replanting",""))&IF(COUNTIFS($B$5:$B$200,$B17,$C$5:$C$200,$C17)>1,"; Duplicate visit","")&IF(J17="","",IF(OR(J17<HMin,J17>HMax),"; Height out of range",""))&IF(E17="","; No observer","")&IF(G17+H17>0,IF(I17="","; Loss without cause",""),""),3,300)) | Z17: =IF($B17="","",IF(Y17="",0,1+LEN(Y17)-LEN(SUBSTITUTE(Y17,";","")))) -> 0
A18: V014 | B18: A04 | C18: 46039 | D18: Census | E18: FS-2 (field staff) | F18: 380 | G18: 45 | H18: 25 | I18: Wave/scour | J18: 55 | K18: 0 | M18: =IF($B18="","",IFERROR(INDEX(Planting_Log!$B$5:$B$60,MATCH($B18,Planting_Log!$A$5:$A$60,0)),"")) -> Site A - seaward fringe | N18: =IF($B18="","",IFERROR(INDEX(Planting_Log!$D$5:$D$60,MATCH($B18,Planting_Log!$A$5:$A$60,0)),"")) -> 45949 | O18: =IF(OR(N18="",C18=""),"",ROUND((C18-N18)/30.44,1)) -> 3 | P18: =IF(O18="","",IF(O18<2,1,IF(O18<4.5,3,IF(O18<7.5,6,IF(O18<10.5,9,12))))) -> 3 | Q18: =IF($B18="","",IFERROR(INDEX(Planting_Log!$G$5:$G$60,MATCH($B18,Planting_Log!$A$5:$A$60,0)),"")) -> 450 | R18: =IF($B18="","",SUMIFS($K$5:$K$200,$B$5:$B$200,$B18,$C$5:$C$200,"<"&$C18)) -> 0 | S18: =IF(Q18="","",Q18+R18) -> 450 | T18: =IF(OR(S18="",S18=0),"",F18/S18) -> 0.84444444 | U18: =IF(OR(Q18="",Q18=0),"",F18/Q18) -> 0.84444444 | V18: =IF($B18="","",IF(COUNTIFS($B$5:$B$200,$B18,$C$5:$C$200,"<"&$C18)=0,"",SUMPRODUCT(MAX(($B$5:$B$200=$B18)*($C$5:$C$200<$C18)*$C$5:$C$200)))) -> 45980 | W18: =IF(V18="","",SUMIFS($F$5:$F$200,$B$5:$B$200,$B18,$C$5:$C$200,V18)) -> 425 | X18: =IF($B18="","",IF(V18="",0,SUMIFS($K$5:$K$200,$B$5:$B$200,$B18,$C$5:$C$200,">="&V18,$C$5:$C$200,"<"&$C18))) -> 0 | Y18: =IF($B18="","",MID(IF(M18="","; Unknown plot","")&IF(N18="","",IF(C18<N18,"; Visit before planting",""))&IF(S18="","",IF(F18+G18+H18<>S18,"; Count mismatch",""))&IF(W18="","",IF(F18>W18+X18,"; Alive rose without replanting",""))&IF(COUNTIFS($B$5:$B$200,$B18,$C$5:$C$200,$C18)>1,"; Duplicate visit","")&IF(J18="","",IF(OR(J18<HMin,J18>HMax),"; Height out of range",""))&IF(E18="","; No observer","")&IF(G18+H18>0,IF(I18="","; Loss without cause",""),""),3,300)) | Z18: =IF($B18="","",IF(Y18="",0,1+LEN(Y18)-LEN(SUBSTITUTE(Y18,";","")))) -> 0
A19: V015 | B19: A04 | C19: 46130 | D19: Census | E19: FS-2 (field staff) | F19: 300 | G19: 95 | H19: 55 | I19: Barnacles | J19: 65 | K19: 0 | M19: =IF($B19="","",IFERROR(INDEX(Planting_Log!$B$5:$B$60,MATCH($B19,Planting_Log!$A$5:$A$60,0)),"")) -> Site A - seaward fringe | N19: =IF($B19="","",IFERROR(INDEX(Planting_Log!$D$5:$D$60,MATCH($B19,Planting_Log!$A$5:$A$60,0)),"")) -> 45949 | O19: =IF(OR(N19="",C19=""),"",ROUND((C19-N19)/30.44,1)) -> 5.9 | P19: =IF(O19="","",IF(O19<2,1,IF(O19<4.5,3,IF(O19<7.5,6,IF(O19<10.5,9,12))))) -> 6 | Q19: =IF($B19="","",IFERROR(INDEX(Planting_Log!$G$5:$G$60,MATCH($B19,Planting_Log!$A$5:$A$60,0)),"")) -> 450 | R19: =IF($B19="","",SUMIFS($K$5:$K$200,$B$5:$B$200,$B19,$C$5:$C$200,"<"&$C19)) -> 0 | S19: =IF(Q19="","",Q19+R19) -> 450 | T19: =IF(OR(S19="",S19=0),"",F19/S19) -> 0.66666667 | U19: =IF(OR(Q19="",Q19=0),"",F19/Q19) -> 0.66666667 | V19: =IF($B19="","",IF(COUNTIFS($B$5:$B$200,$B19,$C$5:$C$200,"<"&$C19)=0,"",SUMPRODUCT(MAX(($B$5:$B$200=$B19)*($C$5:$C$200<$C19)*$C$5:$C$200)))) -> 46039 | W19: =IF(V19="","",SUMIFS($F$5:$F$200,$B$5:$B$200,$B19,$C$5:$C$200,V19)) -> 380 | X19: =IF($B19="","",IF(V19="",0,SUMIFS($K$5:$K$200,$B$5:$B$200,$B19,$C$5:$C$200,">="&V19,$C$5:$C$200,"<"&$C19))) -> 0 | Y19: =IF($B19="","",MID(IF(M19="","; Unknown plot","")&IF(N19="","",IF(C19<N19,"; Visit before planting",""))&IF(S19="","",IF(F19+G19+H19<>S19,"; Count mismatch",""))&IF(W19="","",IF(F19>W19+X19,"; Alive rose without replanting",""))&IF(COUNTIFS($B$5:$B$200,$B19,$C$5:$C$200,$C19)>1,"; Duplicate visit","")&IF(J19="","",IF(OR(J19<HMin,J19>HMax),"; Height out of range",""))&IF(E19="","; No observer","")&IF(G19+H19>0,IF(I19="","; Loss without cause",""),""),3,300)) | Z19: =IF($B19="","",IF(Y19="",0,1+LEN(Y19)-LEN(SUBSTITUTE(Y19,";","")))) -> 0
A20: V016 | B20: B01 | C20: 46077 | D20: Census | E20: PL-2 (partner lead) | F20: 575 | G20: 15 | H20: 10 | J20: 46 | K20: 0 | M20: =IF($B20="","",IFERROR(INDEX(Planting_Log!$B$5:$B$60,MATCH($B20,Planting_Log!$A$5:$A$60,0)),"")) -> Site B - pond dyke | N20: =IF($B20="","",IFERROR(INDEX(Planting_Log!$D$5:$D$60,MATCH($B20,Planting_Log!$A$5:$A$60,0)),"")) -> 46046 | O20: =IF(OR(N20="",C20=""),"",ROUND((C20-N20)/30.44,1)) -> 1 | P20: =IF(O20="","",IF(O20<2,1,IF(O20<4.5,3,IF(O20<7.5,6,IF(O20<10.5,9,12))))) -> 1 | Q20: =IF($B20="","",IFERROR(INDEX(Planting_Log!$G$5:$G$60,MATCH($B20,Planting_Log!$A$5:$A$60,0)),"")) -> 600 | R20: =IF($B20="","",SUMIFS($K$5:$K$200,$B$5:$B$200,$B20,$C$5:$C$200,"<"&$C20)) -> 0 | S20: =IF(Q20="","",Q20+R20) -> 600 | T20: =IF(OR(S20="",S20=0),"",F20/S20) -> 0.95833333 | U20: =IF(OR(Q20="",Q20=0),"",F20/Q20) -> 0.95833333 | V20: =IF($B20="","",IF(COUNTIFS($B$5:$B$200,$B20,$C$5:$C$200,"<"&$C20)=0,"",SUMPRODUCT(MAX(($B$5:$B$200=$B20)*($C$5:$C$200<$C20)*$C$5:$C$200)))) | W20: =IF(V20="","",SUMIFS($F$5:$F$200,$B$5:$B$200,$B20,$C$5:$C$200,V20)) | X20: =IF($B20="","",IF(V20="",0,SUMIFS($K$5:$K$200,$B$5:$B$200,$B20,$C$5:$C$200,">="&V20,$C$5:$C$200,"<"&$C20))) -> 0 | Y20: =IF($B20="","",MID(IF(M20="","; Unknown plot","")&IF(N20="","",IF(C20<N20,"; Visit before planting",""))&IF(S20="","",IF(F20+G20+H20<>S20,"; Count mismatch",""))&IF(W20="","",IF(F20>W20+X20,"; Alive rose without replanting",""))&IF(COUNTIFS($B$5:$B$200,$B20,$C$5:$C$200,$C20)>1,"; Duplicate visit","")&IF(J20="","",IF(OR(J20<HMin,J20>HMax),"; Height out of range",""))&IF(E20="","; No observer","")&IF(G20+H20>0,IF(I20="","; Loss without cause",""),""),3,300)) -> Loss without cause | Z20: =IF($B20="","",IF(Y20="",0,1+LEN(Y20)-LEN(SUBSTITUTE(Y20,";","")))) -> 1
A21: V017 | B21: B01 | C21: 46137 | D21: Census | E21: PL-2 (partner lead) | F21: 540 | G21: 35 | H21: 25 | I21: Crab damage | J21: 52 | K21: 0 | M21: =IF($B21="","",IFERROR(INDEX(Planting_Log!$B$5:$B$60,MATCH($B21,Planting_Log!$A$5:$A$60,0)),"")) -> Site B - pond dyke | N21: =IF($B21="","",IFERROR(INDEX(Planting_Log!$D$5:$D$60,MATCH($B21,Planting_Log!$A$5:$A$60,0)),"")) -> 46046 | O21: =IF(OR(N21="",C21=""),"",ROUND((C21-N21)/30.44,1)) -> 3 | P21: =IF(O21="","",IF(O21<2,1,IF(O21<4.5,3,IF(O21<7.5,6,IF(O21<10.5,9,12))))) -> 3 | Q21: =IF($B21="","",IFERROR(INDEX(Planting_Log!$G$5:$G$60,MATCH($B21,Planting_Log!$A$5:$A$60,0)),"")) -> 600 | R21: =IF($B21="","",SUMIFS($K$5:$K$200,$B$5:$B$200,$B21,$C$5:$C$200,"<"&$C21)) -> 0 | S21: =IF(Q21="","",Q21+R21) -> 600 | T21: =IF(OR(S21="",S21=0),"",F21/S21) -> 0.9 | U21: =IF(OR(Q21="",Q21=0),"",F21/Q21) -> 0.9 | V21: =IF($B21="","",IF(COUNTIFS($B$5:$B$200,$B21,$C$5:$C$200,"<"&$C21)=0,"",SUMPRODUCT(MAX(($B$5:$B$200=$B21)*($C$5:$C$200<$C21)*$C$5:$C$200)))) -> 46077 | W21: =IF(V21="","",SUMIFS($F$5:$F$200,$B$5:$B$200,$B21,$C$5:$C$200,V21)) -> 575 | X21: =IF($B21="","",IF(V21="",0,SUMIFS($K$5:$K$200,$B$5:$B$200,$B21,$C$5:$C$200,">="&V21,$C$5:$C$200,"<"&$C21))) -> 0 | Y21: =IF($B21="","",MID(IF(M21="","; Unknown plot","")&IF(N21="","",IF(C21<N21,"; Visit before planting",""))&IF(S21="","",IF(F21+G21+H21<>S21,"; Count mismatch",""))&IF(W21="","",IF(F21>W21+X21,"; Alive rose without replanting",""))&IF(COUNTIFS($B$5:$B$200,$B21,$C$5:$C$200,$C21)>1,"; Duplicate visit","")&IF(J21="","",IF(OR(J21<HMin,J21>HMax),"; Height out of range",""))&IF(E21="","; No observer","")&IF(G21+H21>0,IF(I21="","; Loss without cause",""),""),3,300)) | Z21: =IF($B21="","",IF(Y21="",0,1+LEN(Y21)-LEN(SUBSTITUTE(Y21,";","")))) -> 0
A22: V018 | B22: B01 | C22: 46228 | D22: Census | E22: FS-1 (field staff) | F22: 510 | G22: 55 | H22: 35 | I22: Crab damage | J22: 63 | K22: 0 | M22: =IF($B22="","",IFERROR(INDEX(Planting_Log!$B$5:$B$60,MATCH($B22,Planting_Log!$A$5:$A$60,0)),"")) -> Site B - pond dyke | N22: =IF($B22="","",IFERROR(INDEX(Planting_Log!$D$5:$D$60,MATCH($B22,Planting_Log!$A$5:$A$60,0)),"")) -> 46046 | O22: =IF(OR(N22="",C22=""),"",ROUND((C22-N22)/30.44,1)) -> 6 | P22: =IF(O22="","",IF(O22<2,1,IF(O22<4.5,3,IF(O22<7.5,6,IF(O22<10.5,9,12))))) -> 6 | Q22: =IF($B22="","",IFERROR(INDEX(Planting_Log!$G$5:$G$60,MATCH($B22,Planting_Log!$A$5:$A$60,0)),"")) -> 600 | R22: =IF($B22="","",SUMIFS($K$5:$K$200,$B$5:$B$200,$B22,$C$5:$C$200,"<"&$C22)) -> 0 | S22: =IF(Q22="","",Q22+R22) -> 600 | T22: =IF(OR(S22="",S22=0),"",F22/S22) -> 0.85 | U22: =IF(OR(Q22="",Q22=0),"",F22/Q22) -> 0.85 | V22: =IF($B22="","",IF(COUNTIFS($B$5:$B$200,$B22,$C$5:$C$200,"<"&$C22)=0,"",SUMPRODUCT(MAX(($B$5:$B$200=$B22)*($C$5:$C$200<$C22)*$C$5:$C$200)))) -> 46137 | W22: =IF(V22="","",SUMIFS($F$5:$F$200,$B$5:$B$200,$B22,$C$5:$C$200,V22)) -> 540 | X22: =IF($B22="","",IF(V22="",0,SUMIFS($K$5:$K$200,$B$5:$B$200,$B22,$C$5:$C$200,">="&V22,$C$5:$C$200,"<"&$C22))) -> 0 | Y22: =IF($B22="","",MID(IF(M22="","; Unknown plot","")&IF(N22="","",IF(C22<N22,"; Visit before planting",""))&IF(S22="","",IF(F22+G22+H22<>S22,"; Count mismatch",""))&IF(W22="","",IF(F22>W22+X22,"; Alive rose without replanting",""))&IF(COUNTIFS($B$5:$B$200,$B22,$C$5:$C$200,$C22)>1,"; Duplicate visit","")&IF(J22="","",IF(OR(J22<HMin,J22>HMax),"; Height out of range",""))&IF(E22="","; No observer","")&IF(G22+H22>0,IF(I22="","; Loss without cause",""),""),3,300)) | Z22: =IF($B22="","",IF(Y22="",0,1+LEN(Y22)-LEN(SUBSTITUTE(Y22,";","")))) -> 0
A23: V019 | B23: B02 | C23: 46077 | D23: Census | E23: PL-2 (partner lead) | F23: 580 | G23: 12 | H23: 8 | I23: Crab damage | J23: 47 | K23: 0 | M23: =IF($B23="","",IFERROR(INDEX(Planting_Log!$B$5:$B$60,MATCH($B23,Planting_Log!$A$5:$A$60,0)),"")) -> Site B - pond dyke | N23: =IF($B23="","",IFERROR(INDEX(Planting_Log!$D$5:$D$60,MATCH($B23,Planting_Log!$A$5:$A$60,0)),"")) -> 46046 | O23: =IF(OR(N23="",C23=""),"",ROUND((C23-N23)/30.44,1)) -> 1 | P23: =IF(O23="","",IF(O23<2,1,IF(O23<4.5,3,IF(O23<7.5,6,IF(O23<10.5,9,12))))) -> 1 | Q23: =IF($B23="","",IFERROR(INDEX(Planting_Log!$G$5:$G$60,MATCH($B23,Planting_Log!$A$5:$A$60,0)),"")) -> 600 | R23: =IF($B23="","",SUMIFS($K$5:$K$200,$B$5:$B$200,$B23,$C$5:$C$200,"<"&$C23)) -> 0 | S23: =IF(Q23="","",Q23+R23) -> 600 | T23: =IF(OR(S23="",S23=0),"",F23/S23) -> 0.96666667 | U23: =IF(OR(Q23="",Q23=0),"",F23/Q23) -> 0.96666667 | V23: =IF($B23="","",IF(COUNTIFS($B$5:$B$200,$B23,$C$5:$C$200,"<"&$C23)=0,"",SUMPRODUCT(MAX(($B$5:$B$200=$B23)*($C$5:$C$200<$C23)*$C$5:$C$200)))) | W23: =IF(V23="","",SUMIFS($F$5:$F$200,$B$5:$B$200,$B23,$C$5:$C$200,V23)) | X23: =IF($B23="","",IF(V23="",0,SUMIFS($K$5:$K$200,$B$5:$B$200,$B23,$C$5:$C$200,">="&V23,$C$5:$C$200,"<"&$C23))) -> 0 | Y23: =IF($B23="","",MID(IF(M23="","; Unknown plot","")&IF(N23="","",IF(C23<N23,"; Visit before planting",""))&IF(S23="","",IF(F23+G23+H23<>S23,"; Count mismatch",""))&IF(W23="","",IF(F23>W23+X23,"; Alive rose without replanting",""))&IF(COUNTIFS($B$5:$B$200,$B23,$C$5:$C$200,$C23)>1,"; Duplicate visit","")&IF(J23="","",IF(OR(J23<HMin,J23>HMax),"; Height out of range",""))&IF(E23="","; No observer","")&IF(G23+H23>0,IF(I23="","; Loss without cause",""),""),3,300)) | Z23: =IF($B23="","",IF(Y23="",0,1+LEN(Y23)-LEN(SUBSTITUTE(Y23,";","")))) -> 0
A24: V020 | B24: B02 | C24: 46137 | D24: Census | E24: PL-2 (partner lead) | F24: 545 | G24: 35 | H24: 20 | I24: Crab damage | J24: 53 | K24: 0 | M24: =IF($B24="","",IFERROR(INDEX(Planting_Log!$B$5:$B$60,MATCH($B24,Planting_Log!$A$5:$A$60,0)),"")) -> Site B - pond dyke | N24: =IF($B24="","",IFERROR(INDEX(Planting_Log!$D$5:$D$60,MATCH($B24,Planting_Log!$A$5:$A$60,0)),"")) -> 46046 | O24: =IF(OR(N24="",C24=""),"",ROUND((C24-N24)/30.44,1)) -> 3 | P24: =IF(O24="","",IF(O24<2,1,IF(O24<4.5,3,IF(O24<7.5,6,IF(O24<10.5,9,12))))) -> 3 | Q24: =IF($B24="","",IFERROR(INDEX(Planting_Log!$G$5:$G$60,MATCH($B24,Planting_Log!$A$5:$A$60,0)),"")) -> 600 | R24: =IF($B24="","",SUMIFS($K$5:$K$200,$B$5:$B$200,$B24,$C$5:$C$200,"<"&$C24)) -> 0 | S24: =IF(Q24="","",Q24+R24) -> 600 | T24: =IF(OR(S24="",S24=0),"",F24/S24) -> 0.90833333 | U24: =IF(OR(Q24="",Q24=0),"",F24/Q24) -> 0.90833333 | V24: =IF($B24="","",IF(COUNTIFS($B$5:$B$200,$B24,$C$5:$C$200,"<"&$C24)=0,"",SUMPRODUCT(MAX(($B$5:$B$200=$B24)*($C$5:$C$200<$C24)*$C$5:$C$200)))) -> 46077 | W24: =IF(V24="","",SUMIFS($F$5:$F$200,$B$5:$B$200,$B24,$C$5:$C$200,V24)) -> 580 | X24: =IF($B24="","",IF(V24="",0,SUMIFS($K$5:$K$200,$B$5:$B$200,$B24,$C$5:$C$200,">="&V24,$C$5:$C$200,"<"&$C24))) -> 0 | Y24: =IF($B24="","",MID(IF(M24="","; Unknown plot","")&IF(N24="","",IF(C24<N24,"; Visit before planting",""))&IF(S24="","",IF(F24+G24+H24<>S24,"; Count mismatch",""))&IF(W24="","",IF(F24>W24+X24,"; Alive rose without replanting",""))&IF(COUNTIFS($B$5:$B$200,$B24,$C$5:$C$200,$C24)>1,"; Duplicate visit","")&IF(J24="","",IF(OR(J24<HMin,J24>HMax),"; Height out of range",""))&IF(E24="","; No observer","")&IF(G24+H24>0,IF(I24="","; Loss without cause",""),""),3,300)) | Z24: =IF($B24="","",IF(Y24="",0,1+LEN(Y24)-LEN(SUBSTITUTE(Y24,";","")))) -> 0
A25: V021 | B25: B02 | C25: 46228 | D25: Census | E25: FS-1 (field staff) | F25: 562 | G25: 23 | H25: 15 | I25: Crab damage | J25: 62 | K25: 0 | M25: =IF($B25="","",IFERROR(INDEX(Planting_Log!$B$5:$B$60,MATCH($B25,Planting_Log!$A$5:$A$60,0)),"")) -> Site B - pond dyke | N25: =IF($B25="","",IFERROR(INDEX(Planting_Log!$D$5:$D$60,MATCH($B25,Planting_Log!$A$5:$A$60,0)),"")) -> 46046 | O25: =IF(OR(N25="",C25=""),"",ROUND((C25-N25)/30.44,1)) -> 6 | P25: =IF(O25="","",IF(O25<2,1,IF(O25<4.5,3,IF(O25<7.5,6,IF(O25<10.5,9,12))))) -> 6 | Q25: =IF($B25="","",IFERROR(INDEX(Planting_Log!$G$5:$G$60,MATCH($B25,Planting_Log!$A$5:$A$60,0)),"")) -> 600 | R25: =IF($B25="","",SUMIFS($K$5:$K$200,$B$5:$B$200,$B25,$C$5:$C$200,"<"&$C25)) -> 0 | S25: =IF(Q25="","",Q25+R25) -> 600 | T25: =IF(OR(S25="",S25=0),"",F25/S25) -> 0.93666667 | U25: =IF(OR(Q25="",Q25=0),"",F25/Q25) -> 0.93666667 | V25: =IF($B25="","",IF(COUNTIFS($B$5:$B$200,$B25,$C$5:$C$200,"<"&$C25)=0,"",SUMPRODUCT(MAX(($B$5:$B$200=$B25)*($C$5:$C$200<$C25)*$C$5:$C$200)))) -> 46137 | W25: =IF(V25="","",SUMIFS($F$5:$F$200,$B$5:$B$200,$B25,$C$5:$C$200,V25)) -> 545 | X25: =IF($B25="","",IF(V25="",0,SUMIFS($K$5:$K$200,$B$5:$B$200,$B25,$C$5:$C$200,">="&V25,$C$5:$C$200,"<"&$C25))) -> 0 | Y25: =IF($B25="","",MID(IF(M25="","; Unknown plot","")&IF(N25="","",IF(C25<N25,"; Visit before planting",""))&IF(S25="","",IF(F25+G25+H25<>S25,"; Count mismatch",""))&IF(W25="","",IF(F25>W25+X25,"; Alive rose without replanting",""))&IF(COUNTIFS($B$5:$B$200,$B25,$C$5:$C$200,$C25)>1,"; Duplicate visit","")&IF(J25="","",IF(OR(J25<HMin,J25>HMax),"; Height out of range",""))&IF(E25="","; No observer","")&IF(G25+H25>0,IF(I25="","; Loss without cause",""),""),3,300)) -> Alive rose without replanting | Z25: =IF($B25="","",IF(Y25="",0,1+LEN(Y25)-LEN(SUBSTITUTE(Y25,";","")))) -> 1
A26: V022 | B26: B03 | C26: 46077 | D26: Census | E26: PL-2 (partner lead) | F26: 520 | G26: 20 | H26: 10 | I26: Sediment burial | J26: 45 | K26: 0 | M26: =IF($B26="","",IFERROR(INDEX(Planting_Log!$B$5:$B$60,MATCH($B26,Planting_Log!$A$5:$A$60,0)),"")) -> Site B - pond dyke | N26: =IF($B26="","",IFERROR(INDEX(Planting_Log!$D$5:$D$60,MATCH($B26,Planting_Log!$A$5:$A$60,0)),"")) -> 46046 | O26: =IF(OR(N26="",C26=""),"",ROUND((C26-N26)/30.44,1)) -> 1 | P26: =IF(O26="","",IF(O26<2,1,IF(O26<4.5,3,IF(O26<7.5,6,IF(O26<10.5,9,12))))) -> 1 | Q26: =IF($B26="","",IFERROR(INDEX(Planting_Log!$G$5:$G$60,MATCH($B26,Planting_Log!$A$5:$A$60,0)),"")) -> 550 | R26: =IF($B26="","",SUMIFS($K$5:$K$200,$B$5:$B$200,$B26,$C$5:$C$200,"<"&$C26)) -> 0 | S26: =IF(Q26="","",Q26+R26) -> 550 | T26: =IF(OR(S26="",S26=0),"",F26/S26) -> 0.94545455 | U26: =IF(OR(Q26="",Q26=0),"",F26/Q26) -> 0.94545455 | V26: =IF($B26="","",IF(COUNTIFS($B$5:$B$200,$B26,$C$5:$C$200,"<"&$C26)=0,"",SUMPRODUCT(MAX(($B$5:$B$200=$B26)*($C$5:$C$200<$C26)*$C$5:$C$200)))) | W26: =IF(V26="","",SUMIFS($F$5:$F$200,$B$5:$B$200,$B26,$C$5:$C$200,V26)) | X26: =IF($B26="","",IF(V26="",0,SUMIFS($K$5:$K$200,$B$5:$B$200,$B26,$C$5:$C$200,">="&V26,$C$5:$C$200,"<"&$C26))) -> 0 | Y26: =IF($B26="","",MID(IF(M26="","; Unknown plot","")&IF(N26="","",IF(C26<N26,"; Visit before planting",""))&IF(S26="","",IF(F26+G26+H26<>S26,"; Count mismatch",""))&IF(W26="","",IF(F26>W26+X26,"; Alive rose without replanting",""))&IF(COUNTIFS($B$5:$B$200,$B26,$C$5:$C$200,$C26)>1,"; Duplicate visit","")&IF(J26="","",IF(OR(J26<HMin,J26>HMax),"; Height out of range",""))&IF(E26="","; No observer","")&IF(G26+H26>0,IF(I26="","; Loss without cause",""),""),3,300)) | Z26: =IF($B26="","",IF(Y26="",0,1+LEN(Y26)-LEN(SUBSTITUTE(Y26,";","")))) -> 0
A27: V023 | B27: B3 | C27: 46137 | D27: Census | E27: PL-2 (partner lead) | F27: 455 | G27: 60 | H27: 35 | I27: Sediment burial | J27: 51 | K27: 0 | M27: =IF($B27="","",IFERROR(INDEX(Planting_Log!$B$5:$B$60,MATCH($B27,Planting_Log!$A$5:$A$60,0)),"")) | N27: =IF($B27="","",IFERROR(INDEX(Planting_Log!$D$5:$D$60,MATCH($B27,Planting_Log!$A$5:$A$60,0)),"")) | O27: =IF(OR(N27="",C27=""),"",ROUND((C27-N27)/30.44,1)) | P27: =IF(O27="","",IF(O27<2,1,IF(O27<4.5,3,IF(O27<7.5,6,IF(O27<10.5,9,12))))) | Q27: =IF($B27="","",IFERROR(INDEX(Planting_Log!$G$5:$G$60,MATCH($B27,Planting_Log!$A$5:$A$60,0)),"")) | R27: =IF($B27="","",SUMIFS($K$5:$K$200,$B$5:$B$200,$B27,$C$5:$C$200,"<"&$C27)) -> 0 | S27: =IF(Q27="","",Q27+R27) | T27: =IF(OR(S27="",S27=0),"",F27/S27) | U27: =IF(OR(Q27="",Q27=0),"",F27/Q27) | V27: =IF($B27="","",IF(COUNTIFS($B$5:$B$200,$B27,$C$5:$C$200,"<"&$C27)=0,"",SUMPRODUCT(MAX(($B$5:$B$200=$B27)*($C$5:$C$200<$C27)*$C$5:$C$200)))) | W27: =IF(V27="","",SUMIFS($F$5:$F$200,$B$5:$B$200,$B27,$C$5:$C$200,V27)) | X27: =IF($B27="","",IF(V27="",0,SUMIFS($K$5:$K$200,$B$5:$B$200,$B27,$C$5:$C$200,">="&V27,$C$5:$C$200,"<"&$C27))) -> 0 | Y27: =IF($B27="","",MID(IF(M27="","; Unknown plot","")&IF(N27="","",IF(C27<N27,"; Visit before planting",""))&IF(S27="","",IF(F27+G27+H27<>S27,"; Count mismatch",""))&IF(W27="","",IF(F27>W27+X27,"; Alive rose without replanting",""))&IF(COUNTIFS($B$5:$B$200,$B27,$C$5:$C$200,$C27)>1,"; Duplicate visit","")&IF(J27="","",IF(OR(J27<HMin,J27>HMax),"; Height out of range",""))&IF(E27="","; No observer","")&IF(G27+H27>0,IF(I27="","; Loss without cause",""),""),3,300)) -> Unknown plot | Z27: =IF($B27="","",IF(Y27="",0,1+LEN(Y27)-LEN(SUBSTITUTE(Y27,";","")))) -> 1
A28: V024 | B28: B03 | C28: 46228 | D28: Census | E28: FS-1 (field staff) | F28: 365 | G28: 115 | H28: 70 | I28: Sediment burial | J28: 58 | K28: 0 | L28: Silt over the lower rows | M28: =IF($B28="","",IFERROR(INDEX(Planting_Log!$B$5:$B$60,MATCH($B28,Planting_Log!$A$5:$A$60,0)),"")) -> Site B - pond dyke | N28: =IF($B28="","",IFERROR(INDEX(Planting_Log!$D$5:$D$60,MATCH($B28,Planting_Log!$A$5:$A$60,0)),"")) -> 46046 | O28: =IF(OR(N28="",C28=""),"",ROUND((C28-N28)/30.44,1)) -> 6 | P28: =IF(O28="","",IF(O28<2,1,IF(O28<4.5,3,IF(O28<7.5,6,IF(O28<10.5,9,12))))) -> 6 | Q28: =IF($B28="","",IFERROR(INDEX(Planting_Log!$G$5:$G$60,MATCH($B28,Planting_Log!$A$5:$A$60,0)),"")) -> 550 | R28: =IF($B28="","",SUMIFS($K$5:$K$200,$B$5:$B$200,$B28,$C$5:$C$200,"<"&$C28)) -> 0 | S28: =IF(Q28="","",Q28+R28) -> 550 | T28: =IF(OR(S28="",S28=0),"",F28/S28) -> 0.66363636 | U28: =IF(OR(Q28="",Q28=0),"",F28/Q28) -> 0.66363636 | V28: =IF($B28="","",IF(COUNTIFS($B$5:$B$200,$B28,$C$5:$C$200,"<"&$C28)=0,"",SUMPRODUCT(MAX(($B$5:$B$200=$B28)*($C$5:$C$200<$C28)*$C$5:$C$200)))) -> 46077 | W28: =IF(V28="","",SUMIFS($F$5:$F$200,$B$5:$B$200,$B28,$C$5:$C$200,V28)) -> 520 | X28: =IF($B28="","",IF(V28="",0,SUMIFS($K$5:$K$200,$B$5:$B$200,$B28,$C$5:$C$200,">="&V28,$C$5:$C$200,"<"&$C28))) -> 0 | Y28: =IF($B28="","",MID(IF(M28="","; Unknown plot","")&IF(N28="","",IF(C28<N28,"; Visit before planting",""))&IF(S28="","",IF(F28+G28+H28<>S28,"; Count mismatch",""))&IF(W28="","",IF(F28>W28+X28,"; Alive rose without replanting",""))&IF(COUNTIFS($B$5:$B$200,$B28,$C$5:$C$200,$C28)>1,"; Duplicate visit","")&IF(J28="","",IF(OR(J28<HMin,J28>HMax),"; Height out of range",""))&IF(E28="","; No observer","")&IF(G28+H28>0,IF(I28="","; Loss without cause",""),""),3,300)) | Z28: =IF($B28="","",IF(Y28="",0,1+LEN(Y28)-LEN(SUBSTITUTE(Y28,";","")))) -> 0
A29: V025 | B29: B04 | C29: 46077 | D29: Census | E29: PL-2 (partner lead) | F29: 585 | G29: 10 | H29: 5 | I29: Crab damage | J29: 46 | K29: 0 | M29: =IF($B29="","",IFERROR(INDEX(Planting_Log!$B$5:$B$60,MATCH($B29,Planting_Log!$A$5:$A$60,0)),"")) -> Site B - pond dyke | N29: =IF($B29="","",IFERROR(INDEX(Planting_Log!$D$5:$D$60,MATCH($B29,Planting_Log!$A$5:$A$60,0)),"")) -> 46046 | O29: =IF(OR(N29="",C29=""),"",ROUND((C29-N29)/30.44,1)) -> 1 | P29: =IF(O29="","",IF(O29<2,1,IF(O29<4.5,3,IF(O29<7.5,6,IF(O29<10.5,9,12))))) -> 1 | Q29: =IF($B29="","",IFERROR(INDEX(Planting_Log!$G$5:$G$60,MATCH($B29,Planting_Log!$A$5:$A$60,0)),"")) -> 600 | R29: =IF($B29="","",SUMIFS($K$5:$K$200,$B$5:$B$200,$B29,$C$5:$C$200,"<"&$C29)) -> 0 | S29: =IF(Q29="","",Q29+R29) -> 600 | T29: =IF(OR(S29="",S29=0),"",F29/S29) -> 0.975 | U29: =IF(OR(Q29="",Q29=0),"",F29/Q29) -> 0.975 | V29: =IF($B29="","",IF(COUNTIFS($B$5:$B$200,$B29,$C$5:$C$200,"<"&$C29)=0,"",SUMPRODUCT(MAX(($B$5:$B$200=$B29)*($C$5:$C$200<$C29)*$C$5:$C$200)))) | W29: =IF(V29="","",SUMIFS($F$5:$F$200,$B$5:$B$200,$B29,$C$5:$C$200,V29)) | X29: =IF($B29="","",IF(V29="",0,SUMIFS($K$5:$K$200,$B$5:$B$200,$B29,$C$5:$C$200,">="&V29,$C$5:$C$200,"<"&$C29))) -> 0 | Y29: =IF($B29="","",MID(IF(M29="","; Unknown plot","")&IF(N29="","",IF(C29<N29,"; Visit before planting",""))&IF(S29="","",IF(F29+G29+H29<>S29,"; Count mismatch",""))&IF(W29="","",IF(F29>W29+X29,"; Alive rose without replanting",""))&IF(COUNTIFS($B$5:$B$200,$B29,$C$5:$C$200,$C29)>1,"; Duplicate visit","")&IF(J29="","",IF(OR(J29<HMin,J29>HMax),"; Height out of range",""))&IF(E29="","; No observer","")&IF(G29+H29>0,IF(I29="","; Loss without cause",""),""),3,300)) | Z29: =IF($B29="","",IF(Y29="",0,1+LEN(Y29)-LEN(SUBSTITUTE(Y29,";","")))) -> 0
A30: V026 | B30: B04 | C30: 46137 | D30: Census | E30: PL-2 (partner lead) | F30: 560 | G30: 25 | H30: 15 | I30: Crab damage | J30: 850 | K30: 0 | M30: =IF($B30="","",IFERROR(INDEX(Planting_Log!$B$5:$B$60,MATCH($B30,Planting_Log!$A$5:$A$60,0)),"")) -> Site B - pond dyke | N30: =IF($B30="","",IFERROR(INDEX(Planting_Log!$D$5:$D$60,MATCH($B30,Planting_Log!$A$5:$A$60,0)),"")) -> 46046 | O30: =IF(OR(N30="",C30=""),"",ROUND((C30-N30)/30.44,1)) -> 3 | P30: =IF(O30="","",IF(O30<2,1,IF(O30<4.5,3,IF(O30<7.5,6,IF(O30<10.5,9,12))))) -> 3 | Q30: =IF($B30="","",IFERROR(INDEX(Planting_Log!$G$5:$G$60,MATCH($B30,Planting_Log!$A$5:$A$60,0)),"")) -> 600 | R30: =IF($B30="","",SUMIFS($K$5:$K$200,$B$5:$B$200,$B30,$C$5:$C$200,"<"&$C30)) -> 0 | S30: =IF(Q30="","",Q30+R30) -> 600 | T30: =IF(OR(S30="",S30=0),"",F30/S30) -> 0.93333333 | U30: =IF(OR(Q30="",Q30=0),"",F30/Q30) -> 0.93333333 | V30: =IF($B30="","",IF(COUNTIFS($B$5:$B$200,$B30,$C$5:$C$200,"<"&$C30)=0,"",SUMPRODUCT(MAX(($B$5:$B$200=$B30)*($C$5:$C$200<$C30)*$C$5:$C$200)))) -> 46077 | W30: =IF(V30="","",SUMIFS($F$5:$F$200,$B$5:$B$200,$B30,$C$5:$C$200,V30)) -> 585 | X30: =IF($B30="","",IF(V30="",0,SUMIFS($K$5:$K$200,$B$5:$B$200,$B30,$C$5:$C$200,">="&V30,$C$5:$C$200,"<"&$C30))) -> 0 | Y30: =IF($B30="","",MID(IF(M30="","; Unknown plot","")&IF(N30="","",IF(C30<N30,"; Visit before planting",""))&IF(S30="","",IF(F30+G30+H30<>S30,"; Count mismatch",""))&IF(W30="","",IF(F30>W30+X30,"; Alive rose without replanting",""))&IF(COUNTIFS($B$5:$B$200,$B30,$C$5:$C$200,$C30)>1,"; Duplicate visit","")&IF(J30="","",IF(OR(J30<HMin,J30>HMax),"; Height out of range",""))&IF(E30="","; No observer","")&IF(G30+H30>0,IF(I30="","; Loss without cause",""),""),3,300)) -> Height out of range | Z30: =IF($B30="","",IF(Y30="",0,1+LEN(Y30)-LEN(SUBSTITUTE(Y30,";","")))) -> 1
A31: V027 | B31: B04 | C31: 46228 | D31: Census | E31: FS-1 (field staff) | F31: 535 | G31: 40 | H31: 25 | I31: Crab damage | J31: 63 | K31: 0 | M31: =IF($B31="","",IFERROR(INDEX(Planting_Log!$B$5:$B$60,MATCH($B31,Planting_Log!$A$5:$A$60,0)),"")) -> Site B - pond dyke | N31: =IF($B31="","",IFERROR(INDEX(Planting_Log!$D$5:$D$60,MATCH($B31,Planting_Log!$A$5:$A$60,0)),"")) -> 46046 | O31: =IF(OR(N31="",C31=""),"",ROUND((C31-N31)/30.44,1)) -> 6 | P31: =IF(O31="","",IF(O31<2,1,IF(O31<4.5,3,IF(O31<7.5,6,IF(O31<10.5,9,12))))) -> 6 | Q31: =IF($B31="","",IFERROR(INDEX(Planting_Log!$G$5:$G$60,MATCH($B31,Planting_Log!$A$5:$A$60,0)),"")) -> 600 | R31: =IF($B31="","",SUMIFS($K$5:$K$200,$B$5:$B$200,$B31,$C$5:$C$200,"<"&$C31)) -> 0 | S31: =IF(Q31="","",Q31+R31) -> 600 | T31: =IF(OR(S31="",S31=0),"",F31/S31) -> 0.89166667 | U31: =IF(OR(Q31="",Q31=0),"",F31/Q31) -> 0.89166667 | V31: =IF($B31="","",IF(COUNTIFS($B$5:$B$200,$B31,$C$5:$C$200,"<"&$C31)=0,"",SUMPRODUCT(MAX(($B$5:$B$200=$B31)*($C$5:$C$200<$C31)*$C$5:$C$200)))) -> 46137 | W31: =IF(V31="","",SUMIFS($F$5:$F$200,$B$5:$B$200,$B31,$C$5:$C$200,V31)) -> 560 | X31: =IF($B31="","",IF(V31="",0,SUMIFS($K$5:$K$200,$B$5:$B$200,$B31,$C$5:$C$200,">="&V31,$C$5:$C$200,"<"&$C31))) -> 0 | Y31: =IF($B31="","",MID(IF(M31="","; Unknown plot","")&IF(N31="","",IF(C31<N31,"; Visit before planting",""))&IF(S31="","",IF(F31+G31+H31<>S31,"; Count mismatch",""))&IF(W31="","",IF(F31>W31+X31,"; Alive rose without replanting",""))&IF(COUNTIFS($B$5:$B$200,$B31,$C$5:$C$200,$C31)>1,"; Duplicate visit","")&IF(J31="","",IF(OR(J31<HMin,J31>HMax),"; Height out of range",""))&IF(E31="","; No observer","")&IF(G31+H31>0,IF(I31="","; Loss without cause",""),""),3,300)) | Z31: =IF($B31="","",IF(Y31="",0,1+LEN(Y31)-LEN(SUBSTITUTE(Y31,";","")))) -> 0
A32: V028 | B32: C01 | C32: 45761 | D32: Census | E32: PL-3 (partner lead) | F32: 388 | G32: 8 | H32: 4 | I32: Debris/plastic | J32: 30 | K32: 0 | M32: =IF($B32="","",IFERROR(INDEX(Planting_Log!$B$5:$B$60,MATCH($B32,Planting_Log!$A$5:$A$60,0)),"")) -> Site C - sheltered lagoon | N32: =IF($B32="","",IFERROR(INDEX(Planting_Log!$D$5:$D$60,MATCH($B32,Planting_Log!$A$5:$A$60,0)),"")) -> 46095 | O32: =IF(OR(N32="",C32=""),"",ROUND((C32-N32)/30.44,1)) -> -11 | P32: =IF(O32="","",IF(O32<2,1,IF(O32<4.5,3,IF(O32<7.5,6,IF(O32<10.5,9,12))))) -> 1 | Q32: =IF($B32="","",IFERROR(INDEX(Planting_Log!$G$5:$G$60,MATCH($B32,Planting_Log!$A$5:$A$60,0)),"")) -> 400 | R32: =IF($B32="","",SUMIFS($K$5:$K$200,$B$5:$B$200,$B32,$C$5:$C$200,"<"&$C32)) -> 0 | S32: =IF(Q32="","",Q32+R32) -> 400 | T32: =IF(OR(S32="",S32=0),"",F32/S32) -> 0.97 | U32: =IF(OR(Q32="",Q32=0),"",F32/Q32) -> 0.97 | V32: =IF($B32="","",IF(COUNTIFS($B$5:$B$200,$B32,$C$5:$C$200,"<"&$C32)=0,"",SUMPRODUCT(MAX(($B$5:$B$200=$B32)*($C$5:$C$200<$C32)*$C$5:$C$200)))) | W32: =IF(V32="","",SUMIFS($F$5:$F$200,$B$5:$B$200,$B32,$C$5:$C$200,V32)) | X32: =IF($B32="","",IF(V32="",0,SUMIFS($K$5:$K$200,$B$5:$B$200,$B32,$C$5:$C$200,">="&V32,$C$5:$C$200,"<"&$C32))) -> 0 | Y32: =IF($B32="","",MID(IF(M32="","; Unknown plot","")&IF(N32="","",IF(C32<N32,"; Visit before planting",""))&IF(S32="","",IF(F32+G32+H32<>S32,"; Count mismatch",""))&IF(W32="","",IF(F32>W32+X32,"; Alive rose without replanting",""))&IF(COUNTIFS($B$5:$B$200,$B32,$C$5:$C$200,$C32)>1,"; Duplicate visit","")&IF(J32="","",IF(OR(J32<HMin,J32>HMax),"; Height out of range",""))&IF(E32="","; No observer","")&IF(G32+H32>0,IF(I32="","; Loss without cause",""),""),3,300)) -> Visit before planting | Z32: =IF($B32="","",IF(Y32="",0,1+LEN(Y32)-LEN(SUBSTITUTE(Y32,";","")))) -> 1
A33: V029 | B33: C01 | C33: 46186 | D33: Census | E33: PL-3 (partner lead) | F33: 365 | G33: 22 | H33: 13 | I33: Debris/plastic | J33: 38 | K33: 0 | M33: =IF($B33="","",IFERROR(INDEX(Planting_Log!$B$5:$B$60,MATCH($B33,Planting_Log!$A$5:$A$60,0)),"")) -> Site C - sheltered lagoon | N33: =IF($B33="","",IFERROR(INDEX(Planting_Log!$D$5:$D$60,MATCH($B33,Planting_Log!$A$5:$A$60,0)),"")) -> 46095 | O33: =IF(OR(N33="",C33=""),"",ROUND((C33-N33)/30.44,1)) -> 3 | P33: =IF(O33="","",IF(O33<2,1,IF(O33<4.5,3,IF(O33<7.5,6,IF(O33<10.5,9,12))))) -> 3 | Q33: =IF($B33="","",IFERROR(INDEX(Planting_Log!$G$5:$G$60,MATCH($B33,Planting_Log!$A$5:$A$60,0)),"")) -> 400 | R33: =IF($B33="","",SUMIFS($K$5:$K$200,$B$5:$B$200,$B33,$C$5:$C$200,"<"&$C33)) -> 0 | S33: =IF(Q33="","",Q33+R33) -> 400 | T33: =IF(OR(S33="",S33=0),"",F33/S33) -> 0.9125 | U33: =IF(OR(Q33="",Q33=0),"",F33/Q33) -> 0.9125 | V33: =IF($B33="","",IF(COUNTIFS($B$5:$B$200,$B33,$C$5:$C$200,"<"&$C33)=0,"",SUMPRODUCT(MAX(($B$5:$B$200=$B33)*($C$5:$C$200<$C33)*$C$5:$C$200)))) -> 45761 | W33: =IF(V33="","",SUMIFS($F$5:$F$200,$B$5:$B$200,$B33,$C$5:$C$200,V33)) -> 388 | X33: =IF($B33="","",IF(V33="",0,SUMIFS($K$5:$K$200,$B$5:$B$200,$B33,$C$5:$C$200,">="&V33,$C$5:$C$200,"<"&$C33))) -> 0 | Y33: =IF($B33="","",MID(IF(M33="","; Unknown plot","")&IF(N33="","",IF(C33<N33,"; Visit before planting",""))&IF(S33="","",IF(F33+G33+H33<>S33,"; Count mismatch",""))&IF(W33="","",IF(F33>W33+X33,"; Alive rose without replanting",""))&IF(COUNTIFS($B$5:$B$200,$B33,$C$5:$C$200,$C33)>1,"; Duplicate visit","")&IF(J33="","",IF(OR(J33<HMin,J33>HMax),"; Height out of range",""))&IF(E33="","; No observer","")&IF(G33+H33>0,IF(I33="","; Loss without cause",""),""),3,300)) | Z33: =IF($B33="","",IF(Y33="",0,1+LEN(Y33)-LEN(SUBSTITUTE(Y33,";","")))) -> 0
